Workbook

Sheet 📖 Ohjeistus
B2: Velkavapaus.fi Budjetointipohja
B3: Tervetuloa käyttämään budjetointipohjaa!
B6: Miten aloitan?
B8: 1. Aloita "Kuukausittainen budjetti" -välilehdeltä
B9: - Syötä kuukausitulosi keltaisille alueille
B10: - Syötä kuukausimenosi keltaisille alueille
B11: - Pohja laskee automaattisesti yhteenvedot
B13: 2. Seuraa päivittäisiä tuloja ja menoja "Tulot ja menot" -välilehdellä
B14: - Kirjaa jokainen tulo ja meno
B15: - Valitse kategoria pudotusvalikosta
B16: - Yhteenvedot päivittyvät automaattisesti
B18: 3. Hallitse velkojasi "Velkaseuranta" -välilehdellä
... B39: Huom! Keltaiset solut ovat syöttökenttiä, valkoiset ovat automaattisia laskelmia.

Sheet 💰 Kuukausittainen budjetti
B2: Kuukausittainen budjetti
B3: Päivitetty: 04.01.2026
B5: TULOT
B6: Tulolähde | C6: Summa (€/kk)
B7: Palkka (netto) | C7: 0
B8: Sivutulot | C8: 0
B9: Etuudet | C9: 0
B10: Muut tulot | C10: 0
B11: TULOT YHTEENSÄ | C11: =SUM(C7:C10)
B13: MENOT
B14: Menokategoria | C14: Summa (€/kk)
B15: Asuminen
B16: Vuokra/laina | C16: 0
B17: Sähkö | C17: 0
B18: Vesi | C18: 0
B19: Internet | C19: 0
B20: Kotivakuutus | C20: 0
B21: Asuminen yhteensä | C21: =SUM(C16:C20)
B22: Ruoka
B23: Ruokaostokset | C23: 0
B24: Ravintolat/kahvilat | C24: 0
B25: Ruoka yhteensä | C25: =SUM(C23:C24)
B26: Liikenne
B27: Julkinen liikenne | C27: 0
B28: Auto (polttoaine) | C28: 0
B29: Autovakuutus | C29: 0
B30: Autohuolto | C30: 0
B31: Liikenne yhteensä | C31: =SUM(C27:C30)
B32: Velat
B33: Lainan lyhennykset | C33: 0
B34: Luottokortti | C34: 0
B35: Muut velat | C35: 0
B36: Velat yhteensä | C36: =SUM(C33:C35)
B37: Vakuutukset
B38: Henkilövakuutukset | C38: 0
B39: Muut vakuutukset | C39: 0
B40: Vakuutukset yhteensä | C40: =SUM(C38:C39)
B41: Viihde
B42: Suoratoistopalvelut | C42: 0
B43: Harrastukset | C43: 0
...

Sheet 📊 Tulot ja menot
B2: Päivittäinen seuranta
B4: Päivämäärä | C4: Kuvaus | D4: Kategoria | E4: Summa (€) | F4: Tyyppi
E5: 0
E6: 0
E7: 0
E8: 0
E9: 0
E10: 0
E11: 0
E12: 0
E13: 0
E14: 0
E15: 0
E16: 0
... E104: 0
B106: YHTEENVETO
B107: Tulot yhteensä | E107: =SUMIF(F5:F104,"Tulo",E5:E104)
B108: Menot yhteensä | E108: =SUMIF(F5:F104,"Meno",E5:E104)
B109: Nettokassavirta | E109: =E107-E108

Sheet 💳 Velkaseuranta
B2: Velkaseuranta
B4: Velan nimi | C4: Alkuperäinen saldo | D4: Nykyinen saldo | E4: Korko % | F4: Kuukausierä | G4: Jäljellä (kk) | H4: Kokonaiskorko
B5: Velka 1 | C5: 0 | D5: 0 | E5: 0 | F5: 0 | G5: =IF(F5=0,0,D5/F5) | H5: =IF(D5=0,0,(F5*G5)-D5)
B6: Velka 2 | C6: 0 | D6: 0 | E6: 0 | F6: 0 | G6: =IF(F6=0,0,D6/F6) | H6: =IF(D6=0,0,(F6*G6)-D6)
B7: Velka 3 | C7: 0 | D7: 0 | E7: 0 | F7: 0 | G7: =IF(F7=0,0,D7/F7) | H7: =IF(D7=0,0,(F7*G7)-D7)
B8: Velka 4 | C8: 0 | D8: 0 | E8: 0 | F8: 0 | G8: =IF(F8=0,0,D8/F8) | H8: =IF(D8=0,0,(F8*G8)-D8)
B9: Velka 5 | C9: 0 | D9: 0 | E9: 0 | F9: 0 | G9: =IF(F9=0,0,D9/F9) | H9: =IF(D9=0,0,(F9*G9)-D9)
B10: Velka 6 | C10: 0 | D10: 0 | E10: 0 | F10: 0 | G10: =IF(F10=0,0,D10/F10) | H10: =IF(D10=0,0,(F10*G10)-D10)
B11: Velka 7 | C11: 0 | D11: 0 | E11: 0 | F11: 0 | G11: =IF(F11=0,0,D11/F11) | H11: =IF(D11=0,0,(F11*G11)-D11)
B12: Velka 8 | C12: 0 | D12: 0 | E12: 0 | F12: 0 | G12: =IF(F12=0,0,D12/F12) | H12: =IF(D12=0,0,(F12*G12)-D12)
B13: Velka 9 | C13: 0 | D13: 0 | E13: 0 | F13: 0 | G13: =IF(F13=0,0,D13/F13) | H13: =IF(D13=0,0,(F13*G13)-D13)
B14: Velka 10 | C14: 0 | D14: 0 | E14: 0 | F14: 0 | G14: =IF(F14=0,0,D14/F14) | H14: =IF(D14=0,0,(F14*G14)-D14)
B16: YHTEENVETO
B17: Velat yhteensä | D17: =SUM(D5:D14)
B18: Kuukausierät yhteensä | D18: =SUM(F5:F14)
B19: Kokonaiskorot | D19: =SUM(H5:H14)
B20: Keskimääräinen korko | D20: =AVERAGE(E5:E14)

Sheet 🎯 Säästötavoitteet
B2: Säästötavoitteet
B4: Tavoite | C4: Tavoitesumma | D4: Säästetty | E4: Jäljellä | F4: Kuukausia jäljellä | G4: Kuukausisäästö
B5: Tavoite 1 | C5: 0 | D5: 0 | E5: =C5-D5 | F5: 0 | G5: =IF(F5=0,0,E5/F5)
B6: Tavoite 2 | C6: 0 | D6: 0 | E6: =C6-D6 | F6: 0 | G6: =IF(F6=0,0,E6/F6)
B7: Tavoite 3 | C7: 0 | D7: 0 | E7: =C7-D7 | F7: 0 | G7: =IF(F7=0,0,E7/F7)
B8: Tavoite 4 | C8: 0 | D8: 0 | E8: =C8-D8 | F8: 0 | G8: =IF(F8=0,0,E8/F8)
B9: Tavoite 5 | C9: 0 | D9: 0 | E9: =C9-D9 | F9: 0 | G9: =IF(F9=0,0,E9/F9)

Sheet 📅 Vuosikatsaus
B2: Vuosikatsaus
B4: Kuukausi | C4: Tulot | D4: Menot | E4: Säästö/Alijäämä
B5: Tammikuu | C5: 0 | D5: 0 | E5: =C5-D5
B6: Helmikuu | C6: 0 | D6: 0 | E6: =C6-D6
B7: Maaliskuu | C7: 0 | D7: 0 | E7: =C7-D7
B8: Huhtikuu | C8: 0 | D8: 0 | E8: =C8-D8
B9: Toukokuu | C9: 0 | D9: 0 | E9: =C9-D9
B10: Kesäkuu | C10: 0 | D10: 0 | E10: =C10-D10
B11: Heinäkuu | C11: 0 | D11: 0 | E11: =C11-D11
B12: Elokuu | C12: 0 | D12: 0 | E12: =C12-D12
B13: Syyskuu | C13: 0 | D13: 0 | E13: =C13-D13
B14: Lokakuu | C14: 0 | D14: 0 | E14: =C14-D14
B15: Marraskuu | C15: 0 | D15: 0 | E15: =C15-D15
B16: Joulukuu | C16: 0 | D16: 0 | E16: =C16-D16
B17: VUOSI YHTEENSÄ | C17: =SUM(C5:C16) | D17: =SUM(D5:D16) | E17: =SUM(E5:E16)

Sheet 📈 Raportit
B2: Automaattiset raportit
B4: Tämä välilehti päivittyy automaattisesti syöttämiesi tietojen perusteella.
B6: TALOUDELLISET MITTARIT
B7: Kuukausittainen kassavirta | D7: ='💰 Kuukausittainen budjetti'!C11-'💰 Kuukausittainen budjetti'!C42
B8: Säästöaste | D8: ='💰 Kuukausittainen budjetti'!C45
B9: Velat yhteensä | D9: ='💳 Velkaseuranta'!D17
B10: Kuukausittaiset velkaerät | D10: ='💳 Velkaseuranta'!D18
B11: Velkasuhde (velkaerät/tulot) | D11: =IF('💰 Kuukausittainen budjetti'!C11=0,0,'💳 Velkaseuranta'!D18/'💰 Kuukausittainen budjetti'!C11)
